Workbook

Sheet DATA
B1: 2025 | C1: 2024 | D1: 2023 | E1: 2022 | F1: 2021
A2: BALANCE SHEET
H3: Giá CP
A4: TÀI SẢN | H4: SLCP ĐLH
A6: A - TÀI SẢN NGẮN HẠN
A8: I. Tiền và các khoản tương đương tiền
A9: 1. Tiền
A10: 2. Các khoản tương đương tiền
A12: II. Đầu tư tài chính ngắn hạn
A13: 1. Chứng khoán kinh doanh
A14: 2. Dự phòng giảm giá chứng khoán kinh doanh (*)
A15: 3. Đầu tư nắm giữ đến ngày đáo hạn
A17: III. Các khoản phải thu ngắn hạn
A18: 1. Phải thu ngắn hạn của khách hàng
A19: 2. Trả trước cho người bán ngắn hạn
A20: 3. Phải thu nội bộ ngắn hạn
... A47: 7. Dự phòng phải thu dài hạn khó đòi (*)
A49: II. Tài sản cố định | B49: =SUM(B50,B53,B56) -> 0 | C49: =SUM(C50,C53,C56) -> 0 | D49: =SUM(D50,D53,D56) -> 0 | E49: =SUM(E50,E53,E56) -> 0 | F49: =SUM(F50,F53,F56) -> 0
A50: 1. Tài sản cố định hữu hình | B50: =SUM(B51:B52) -> 0 | C50: =SUM(C51:C52) -> 0 | D50: =SUM(D51:D52) -> 0 | E50: =SUM(E51:E52) -> 0 | F50: =SUM(F51:F52) -> 0
A51: - Nguyên giá
A52: - Giá trị hao mòn luỹ kế (*)
A53: 2. Tài sản cố định thuê tài chính | B53: =SUM(B54:B55) -> 0 | C53: =SUM(C54:C55) -> 0 | D53: =SUM(D54:D55) -> 0 | E53: =SUM(E54:E55) -> 0 | F53: =SUM(F54:F55) -> 0
A54: - Nguyên giá
A55: - Giá trị hao mòn luỹ kế (*)
A56: 3. Tài sản cố định vô hình | B56: =SUM(B57:B58) -> 0 | C56: =SUM(C57:C58) -> 0 | D56: =SUM(D57:D58) -> 0 | E56: =SUM(E57:E58) -> 0 | F56: =SUM(F57:F58) -> 0
A57: - Nguyên giá
A58: - Giá trị hao mòn luỹ kế (*)
A60: III. Bất động sản đầu tư | B60: =SUM(B61:B62) -> 0 | C60: =SUM(C61:C62) -> 0 | D60: =SUM(D61:D62) -> 0 | E60: =SUM(E61:E62) -> 0 | F60: =SUM(F61:F62) -> 0
A61: - Nguyên giá
A62: - Giá trị hao mòn luỹ kế (*)
A64: IV. Tài sản dở dang dài hạn
A65: 1. Chi phí sản xuất, kinh doanh dở dang dài hạn
A66: 2. Chi phí xây dựng cơ bản dở dang
A68: V. Đầu tư tài chính dài hạn
A69: 1. Đầu tư vào công ty con
A70: 2. Đầu tư vào công ty liên doanh, liên kết
A71: 3. Đầu tư góp vốn vào đơn vị khác
A72: 4. Dự phòng đầu tư tài chính dài hạn (*)
A73: 5. Đầu tư nắm giữ đến ngày đáo hạn
A75: VI. Tài sản dài hạn khác
...

Sheet PROCESSING
A1: No. | C1: 2025 | D1: 2024 | E1: 2023 | F1: 2022 | G1: 2021
A2: 1 | B2: EBIT | C2: =DATA!B158+DATA!B149+SUM(DATA!B157:B157) -> 0 | D2: =DATA!C158+DATA!C149+SUM(DATA!C157:C157) -> 0 | E2: =DATA!D158+DATA!D149+SUM(DATA!D157:D157) -> 0 | F2: =DATA!E158+DATA!E149+SUM(DATA!E157:E157) -> 0 | G2: =DATA!F158+DATA!F149+SUM(DATA!F157:F157) -> 0
A3: 2 | B3: EBITDA | C3: =IF(DATA!B176="","",C2+DATA!B176) | D3: =IF(DATA!C176="","",D2+DATA!C176) | E3: =IF(DATA!D176="","",E2+DATA!D176) | F3: =IF(DATA!E176="","",F2+DATA!E176) | G3: =IF(DATA!F176="","",G2+DATA!F176)
A4: 3 | B4: Tax Rate | C4: =IFERROR(DATA!B157/DATA!B156,0) -> 0 | D4: =IFERROR(DATA!C157/DATA!C156,0) -> 0 | E4: =IFERROR(DATA!D157/DATA!D156,0) -> 0 | F4: =IFERROR(DATA!E157/DATA!E156,0) -> 0 | G4: =IFERROR(DATA!F157/DATA!F156,0) -> 0
A5: 4 | B5: NOPAT | C5: =IFERROR(C2*(1-C4),0) -> 0 | D5: =IFERROR(D2*(1-D4),0) -> 0 | E5: =IFERROR(E2*(1-E4),0) -> 0 | F5: =IFERROR(F2*(1-F4),0) -> 0 | G5: =IFERROR(G2*(1-G4),0) -> 0
A6: 5 | B6: EPS | C6: =IFERROR(DATA!B158/DATA!$I$4,0) -> 0 | D6: =IFERROR(DATA!C158/DATA!$I$4,0) -> 0 | E6: =IFERROR(DATA!D158/DATA!$I$4,0) -> 0 | F6: =IFERROR(DATA!E158/DATA!$I$4,0) -> 0 | G6: =IFERROR(DATA!F158/DATA!$I$4,0) -> 0
A7: 6 | B7: BVPS | C7: =IFERROR(DATA!B116/DATA!$I$4,0) -> 0 | D7: =IFERROR(DATA!C116/DATA!$I$4,0) -> 0 | E7: =IFERROR(DATA!D116/DATA!$I$4,0) -> 0 | F7: =IFERROR(DATA!E116/DATA!$I$4,0) -> 0 | G7: =IFERROR(DATA!F116/DATA!$I$4,0) -> 0
A8: 7 | B8: Vốn hóa | C8: =IFERROR(DATA!$I$3*DATA!$I$4,0) -> 0 | D8: =IFERROR(DATA!$I$3*DATA!$I$4,0) -> 0 | E8: =IFERROR(DATA!$I$3*DATA!$I$4,0) -> 0 | F8: =IFERROR(DATA!$I$3*DATA!$I$4,0) -> 0 | G8: =IFERROR(DATA!$I$3*DATA!$I$4,0) -> 0
A9: 8 | B9: EV | C9: =IFERROR(C8+DATA!B83-DATA!B8,0) -> 0 | D9: =IFERROR(D8+DATA!C83-DATA!C8,0) -> 0 | E9: =IFERROR(E8+DATA!D83-DATA!D8,0) -> 0 | F9: =IFERROR(F8+DATA!E83-DATA!E8,0) -> 0 | G9: =IFERROR(G8+DATA!F83-DATA!F8,0) -> 0
A10: 9 | B10: FCF | C10: =IFERROR(DATA!B192-DATA!B195,0) -> 0 | D10: =IFERROR(DATA!C192-DATA!C195,0) -> 0 | E10: =IFERROR(DATA!D192-DATA!D195,0) -> 0 | F10: =IFERROR(DATA!E192-DATA!E195,0) -> 0 | G10: =IFERROR(DATA!F192-DATA!F195,0) -> 0
A11: 10 | B11: ΔWC | C11: =DATA!B192-DATA!B182 -> 0 | D11: =DATA!C192-DATA!C182 -> 0 | E11: =DATA!D192-DATA!D182 -> 0 | F11: =DATA!E192-DATA!E182 -> 0 | G11: =DATA!F192-DATA!F182 -> 0 | I11: only indirect cash flow statement
A12: 11 | B12: Forward EPS | C12: =IFERROR(DATA!B221/DATA!I4,0) -> 0 | D12: =IFERROR(DATA!C221/DATA!J4,0) -> 0 | E12: =IFERROR(DATA!D221/DATA!K4,0) -> 0 | F12: =IFERROR(DATA!E221/DATA!L4,0) -> 0 | G12: =IFERROR(DATA!F221/DATA!M4,0) -> 0

Sheet RATIOS
A1: No. | E1: 2025 | F1: 2024 | G1: 2023 | H1: 2022 | I1: 2021
A2: =SUBTOTAL(3,$C$2:C2) -> 1 | B2: PROFITABILITY | C2: Gross Profit Margin | D2: GPM | E2: =IFERROR(DATA!B146/DATA!B144,0) -> 0 | F2: =IFERROR(DATA!C146/DATA!C144,0) -> 0 | G2: =IFERROR(DATA!D146/DATA!D144,0) -> 0 | H2: =IFERROR(DATA!E146/DATA!E144,0) -> 0 | I2: =IFERROR(DATA!F146/DATA!F144,0) -> 0
A3: =SUBTOTAL(3,$C$2:C3) -> 2 | C3: Operating Profit Margin | D3: OPM | E3: =IFERROR(DATA!B152/DATA!B144,0) -> 0 | F3: =IFERROR(DATA!C152/DATA!C144,0) -> 0 | G3: =IFERROR(DATA!D152/DATA!D144,0) -> 0 | H3: =IFERROR(DATA!E152/DATA!E144,0) -> 0 | I3: =IFERROR(DATA!F152/DATA!F144,0) -> 0
A4: =SUBTOTAL(3,$C$2:C4) -> 3 | C4: Net Profit Margin | D4: NPM | E4: =IFERROR(DATA!B158/DATA!B144,0) -> 0 | F4: =IFERROR(DATA!C158/DATA!C144,0) -> 0 | G4: =IFERROR(DATA!D158/DATA!D144,0) -> 0 | H4: =IFERROR(DATA!E158/DATA!E144,0) -> 0 | I4: =IFERROR(DATA!F158/DATA!F144,0) -> 0
A5: =SUBTOTAL(3,$C$2:C5) -> 4 | C5: EBITDA Margin | E5: =IFERROR(IF(PROCESSING!C3="","X",PROCESSING!C3/DATA!B144),0) -> X | F5: =IFERROR(IF(PROCESSING!D3="","X",PROCESSING!D3/DATA!C144),0) -> X | G5: =IFERROR(IF(PROCESSING!E3="","X",PROCESSING!E3/DATA!D144),0) -> X | H5: =IFERROR(IF(PROCESSING!F3="","X",PROCESSING!F3/DATA!E144),0) -> X | I5: =IFERROR(IF(PROCESSING!G3="","X",PROCESSING!G3/DATA!F144),0) -> X | K5: ko có chỉ số này trong BCLCTT trực tiếp
A6: =SUBTOTAL(3,$C$2:C6) -> 5 | C6: Return on Assets | D6: ROA | E6: =IFERROR(DATA!B158/DATA!B81,0) -> 0 | F6: =IFERROR(DATA!C158/DATA!C81,0) -> 0 | G6: =IFERROR(DATA!D158/DATA!D81,0) -> 0 | H6: =IFERROR(DATA!E158/DATA!E81,0) -> 0 | I6: =IFERROR(DATA!F158/DATA!F81,0) -> 0
A7: =SUBTOTAL(3,$C$2:C7) -> 6 | C7: Return on Equity | D7: ROE | E7: =IFERROR(DATA!B158/DATA!B116,0) -> 0 | F7: =IFERROR(DATA!C158/DATA!C116,0) -> 0 | G7: =IFERROR(DATA!D158/DATA!D116,0) -> 0 | H7: =IFERROR(DATA!E158/DATA!E116,0) -> 0 | I7: =IFERROR(DATA!F158/DATA!F116,0) -> 0
A8: =SUBTOTAL(3,$C$2:C8) -> 7 | C8: Return on Invested Capital | D8: ROIC | E8: =IFERROR(PROCESSING!C5/(DATA!B83+DATA!B116-DATA!B8),0) -> 0 | F8: =IFERROR(PROCESSING!D5/(DATA!C83+DATA!C116-DATA!C8),0) -> 0 | G8: =IFERROR(PROCESSING!E5/(DATA!D83+DATA!D116-DATA!D8),0) -> 0 | H8: =IFERROR(PROCESSING!F5/(DATA!E83+DATA!E116-DATA!E8),0) -> 0 | I8: =IFERROR(PROCESSING!G5/(DATA!F83+DATA!F116-DATA!F8),0) -> 0
A9: =SUBTOTAL(3,$C$2:C9) -> 8 | C9: DuPoint Analysis (ROE) | E9: =IFERROR(E4*E20*E17,0) -> 0 | F9: =IFERROR(F4*F20*F17,0) -> 0 | G9: =IFERROR(G4*G20*G17,0) -> 0 | H9: =IFERROR(H4*H20*H17,0) -> 0 | I9: =IFERROR(I4*I20*I17,0) -> 0
A10: =SUBTOTAL(3,$C$2:C10) -> 9 | B10: LIQUIDITY | C10: Current Ratio | E10: =IFERROR(DATA!B6/DATA!B85,0) -> 0 | F10: =IFERROR(DATA!C6/DATA!C85,0) -> 0 | G10: =IFERROR(DATA!D6/DATA!D85,0) -> 0 | H10: =IFERROR(DATA!E6/DATA!E85,0) -> 0 | I10: =IFERROR(DATA!F6/DATA!F85,0) -> 0
A11: =SUBTOTAL(3,$C$2:C11) -> 10 | C11: Quick Ratio | E11: =IFERROR((DATA!B6-DATA!B27)/DATA!B85,0) -> 0 | F11: =IFERROR((DATA!C6-DATA!C27)/DATA!C85,0) -> 0 | G11: =IFERROR((DATA!D6-DATA!D27)/DATA!D85,0) -> 0 | H11: =IFERROR((DATA!E6-DATA!E27)/DATA!E85,0) -> 0 | I11: =IFERROR((DATA!F6-DATA!F27)/DATA!F85,0) -> 0
A12: =SUBTOTAL(3,$C$2:C12) -> 11 | C12: Cash Ratio | E12: =IFERROR(DATA!B8/DATA!B85,0) -> 0 | F12: =IFERROR(DATA!C8/DATA!C85,0) -> 0 | G12: =IFERROR(DATA!D8/DATA!D85,0) -> 0 | H12: =IFERROR(DATA!E8/DATA!E85,0) -> 0 | I12: =IFERROR(DATA!F8/DATA!F85,0) -> 0
A13: =SUBTOTAL(3,$C$2:C13) -> 12 | B13: LEVERAGE/SOLVENCY | C13: Debt-to-Assets | D13: D/A | E13: =IFERROR(DATA!B83/DATA!B81,0) -> 0 | F13: =IFERROR(DATA!C83/DATA!C81,0) -> 0 | G13: =IFERROR(DATA!D83/DATA!D81,0) -> 0 | H13: =IFERROR(DATA!E83/DATA!E81,0) -> 0 | I13: =IFERROR(DATA!F83/DATA!F81,0) -> 0
A14: =SUBTOTAL(3,$C$2:C14) -> 13 | C14: Debt-to-Equity | D14: D/E | E14: =IFERROR(DATA!B83/DATA!B116,0) -> 0 | F14: =IFERROR(DATA!C83/DATA!C116,0) -> 0 | G14: =IFERROR(DATA!D83/DATA!D116,0) -> 0 | H14: =IFERROR(DATA!E83/DATA!E116,0) -> 0 | I14: =IFERROR(DATA!F83/DATA!F116,0) -> 0
A15: =SUBTOTAL(3,$C$2:C15) -> 14 | C15: Debt-to-EBITDA | E15: =IFERROR(IF(PROCESSING!C3="","X",DATA!B83/PROCESSING!C3),0) -> X | F15: =IFERROR(IF(PROCESSING!D3="","X",DATA!C83/PROCESSING!D3),0) -> X | G15: =IFERROR(IF(PROCESSING!E3="","X",DATA!D83/PROCESSING!E3),0) -> X | H15: =IFERROR(IF(PROCESSING!F3="","X",DATA!E83/PROCESSING!F3),0) -> X | I15: =IFERROR(IF(PROCESSING!G3="","X",DATA!F83/PROCESSING!G3),0) -> X | K15: ko có chỉ số này trong BCLCTT trực tiếp
A16: =SUBTOTAL(3,$C$2:C16) -> 15 | C16: Net Debt-to-EBITDA | E16: =IFERROR(IF(PROCESSING!C3="","X",(DATA!B83-DATA!B8)/PROCESSING!C3),0) -> X | F16: =IFERROR(IF(PROCESSING!D3="","X",(DATA!C83-DATA!C8)/PROCESSING!D3),0) -> X | G16: =IFERROR(IF(PROCESSING!E3="","X",(DATA!D83-DATA!D8)/PROCESSING!E3),0) -> X | H16: =IFERROR(IF(PROCESSING!F3="","X",(DATA!E83-DATA!E8)/PROCESSING!F3),0) -> X | I16: =IFERROR(IF(PROCESSING!G3="","X",(DATA!F83-DATA!F8)/PROCESSING!G3),0) -> X | K16: ko có chỉ số này trong BCLCTT trực tiếp
C17: Equity Multiplier | E17: =IFERROR(DATA!B81/DATA!B116,0) -> 0 | F17: =IFERROR(DATA!C81/DATA!C116,0) -> 0 | G17: =IFERROR(DATA!D81/DATA!D116,0) -> 0 | H17: =IFERROR(DATA!E81/DATA!E116,0) -> 0 | I17: =IFERROR(DATA!F81/DATA!F116,0) -> 0
A18: =SUBTOTAL(3,$C$2:C18) -> 17 | C18: Financial Leverage Ratio | D18: FLR | E18: =IFERROR(DATA!B81/DATA!B116,0) -> 0 | F18: =IFERROR(DATA!C81/DATA!C116,0) -> 0 | G18: =IFERROR(DATA!D81/DATA!D116,0) -> 0 | H18: =IFERROR(DATA!E81/DATA!E116,0) -> 0 | I18: =IFERROR(DATA!F81/DATA!F116,0) -> 0
A19: =SUBTOTAL(3,$C$2:C19) -> 18 | C19: Interest Coverage Ratio | D19: ICR | E19: =IFERROR(PROCESSING!C2/DATA!B149,0) -> 0 | F19: =IFERROR(PROCESSING!D2/DATA!C149,0) -> 0 | G19: =IFERROR(PROCESSING!E2/DATA!D149,0) -> 0 | H19: =IFERROR(PROCESSING!F2/DATA!E149,0) -> 0 | I19: =IFERROR(PROCESSING!G2/DATA!F149,0) -> 0
A20: =SUBTOTAL(3,$C$2:C20) -> 19 | B20: EFFIENCY/ACTIVITIES | C20: Total Asset Turnover | E20: =IFERROR(DATA!B144/DATA!B81,0) -> 0 | F20: =IFERROR(DATA!C144/DATA!C81,0) -> 0 | G20: =IFERROR(DATA!D144/DATA!D81,0) -> 0 | H20: =IFERROR(DATA!E144/DATA!E81,0) -> 0 | I20: =IFERROR(DATA!F144/DATA!F81,0) -> 0
A21: =SUBTOTAL(3,$C$2:C21) -> 20 | C21: Fixed Asset Turnover | E21: =IFERROR(DATA!B145/DATA!B49,0) -> 0 | F21: =IFERROR(DATA!C145/DATA!C49,0) -> 0 | G21: =IFERROR(DATA!D145/DATA!D49,0) -> 0 | H21: =IFERROR(DATA!E145/DATA!E49,0) -> 0 | I21: =IFERROR(DATA!F145/DATA!F49,0) -> 0
A22: =SUBTOTAL(3,$C$2:C22) -> 21 | C22: Inventory Turnover | E22: =IFERROR(DATA!B145/DATA!B27,0) -> 0 | F22: =IFERROR(DATA!C145/DATA!C27,0) -> 0 | G22: =IFERROR(DATA!D145/DATA!D27,0) -> 0 | H22: =IFERROR(DATA!E145/DATA!E27,0) -> 0 | I22: =IFERROR(DATA!F145/DATA!F27,0) -> 0
A23: =SUBTOTAL(3,$C$2:C23) -> 22 | C23: Receivables Turnover | E23: =IFERROR(DATA!B144/DATA!B18,0) -> 0 | F23: =IFERROR(DATA!C144/DATA!C18,0) -> 0 | G23: =IFERROR(DATA!D144/DATA!D18,0) -> 0 | H23: =IFERROR(DATA!E144/DATA!E18,0) -> 0 | I23: =IFERROR(DATA!F144/DATA!F18,0) -> 0
A24: =SUBTOTAL(3,$C$2:C24) -> 23 | C24: Payables Turnover | E24: =IFERROR(DATA!B145/DATA!B86,0) -> 0 | F24: =IFERROR(DATA!C145/DATA!C86,0) -> 0 | G24: =IFERROR(DATA!D145/DATA!D86,0) -> 0 | H24: =IFERROR(DATA!E145/DATA!E86,0) -> 0 | I24: =IFERROR(DATA!F145/DATA!F86,0) -> 0
A25: =SUBTOTAL(3,$C$2:C25) -> 24 | C25: Days Sales Outstanding | D25: DSO | E25: =IFERROR((DATA!B18/DATA!B144)*365,0) -> 0 | F25: =IFERROR((DATA!C18/DATA!C144)*365,0) -> 0 | G25: =IFERROR((DATA!D18/DATA!D144)*365,0) -> 0 | H25: =IFERROR((DATA!E18/DATA!E144)*365,0) -> 0 | I25: =IFERROR((DATA!F18/DATA!F144)*365,0) -> 0
A26: =SUBTOTAL(3,$C$2:C26) -> 25 | C26: Days Inventory Outstanding | D26: DIO | E26: =IFERROR((DATA!B27/DATA!B145)*365,0) -> 0 | F26: =IFERROR((DATA!C27/DATA!C145)*365,0) -> 0 | G26: =IFERROR((DATA!D27/DATA!D145)*365,0) -> 0 | H26: =IFERROR((DATA!E27/DATA!E145)*365,0) -> 0 | I26: =IFERROR((DATA!F27/DATA!F145)*365,0) -> 0
A27: =SUBTOTAL(3,$C$2:C27) -> 26 | C27: Days Payable Outstanding | D27: DPO | E27: =IFERROR((DATA!B86/DATA!B145)*365,0) -> 0 | F27: =IFERROR((DATA!C86/DATA!C145)*365,0) -> 0 | G27: =IFERROR((DATA!D86/DATA!D145)*365,0) -> 0 | H27: =IFERROR((DATA!E86/DATA!E145)*365,0) -> 0 | I27: =IFERROR((DATA!F86/DATA!F145)*365,0) -> 0
A28: =SUBTOTAL(3,$C$2:C28) -> 27 | C28: Cash Coversion Cycle | D28: CCC | E28: =E25+E26-E27 -> 0 | F28: =F25+F26-F27 -> 0 | G28: =G25+G26-G27 -> 0 | H28: =H25+H26-H27 -> 0 | I28: =I25+I26-I27 -> 0
A29: =SUBTOTAL(3,$C$2:C29) -> 28 | B29: VALUATION | C29: Price-to-Earnings | D29: P/E | E29: =IFERROR(DATA!$I$3/PROCESSING!C6,0) -> 0 | F29: =IFERROR(DATA!$I$3/PROCESSING!D6,0) -> 0 | G29: =IFERROR(DATA!$I$3/PROCESSING!E6,0) -> 0 | H29: =IFERROR(DATA!$I$3/PROCESSING!F6,0) -> 0 | I29: =IFERROR(DATA!$I$3/PROCESSING!G6,0) -> 0
A30: =SUBTOTAL(3,$C$2:C30) -> 29 | C30: Forward Price-to-Earnings | E30: =IFERROR(DATA!$I$3/PROCESSING!C12,0) -> 0 | F30: =IFERROR(DATA!$I$3/PROCESSING!D12,0) -> 0 | G30: =IFERROR(DATA!$I$3/PROCESSING!E12,0) -> 0 | H30: =IFERROR(DATA!$I$3/PROCESSING!F12,0) -> 0 | I30: =IFERROR(DATA!$I$3/PROCESSING!G12,0) -> 0
A31: =SUBTOTAL(3,$C$2:C31) -> 30 | C31: Price-to-Book | D31: P/B | E31: =IFERROR(DATA!$I$3/PROCESSING!C7,0) -> 0 | F31: =IFERROR(DATA!$I$3/PROCESSING!D7,0) -> 0 | G31: =IFERROR(DATA!$I$3/PROCESSING!E7,0) -> 0 | H31: =IFERROR(DATA!$I$3/PROCESSING!F7,0) -> 0 | I31: =IFERROR(DATA!$I$3/PROCESSING!G7,0) -> 0
A32: =SUBTOTAL(3,$C$2:C32) -> 31 | C32: Price-to-Sales | D32: P/S | E32: =IFERROR(PROCESSING!C8/DATA!B144,0) -> 0 | F32: =IFERROR(PROCESSING!D8/DATA!C144,0) -> 0 | G32: =IFERROR(PROCESSING!E8/DATA!D144,0) -> 0 | H32: =IFERROR(PROCESSING!F8/DATA!E144,0) -> 0 | I32: =IFERROR(PROCESSING!G8/DATA!F144,0) -> 0
A33: =SUBTOTAL(3,$C$2:C33) -> 32 | C33: Price-to-Cash Flow | D33: P/CF | E33: =IFERROR(PROCESSING!C8/DATA!B171,0) -> 0 | F33: =IFERROR(PROCESSING!D8/DATA!C171,0) -> 0 | G33: =IFERROR(PROCESSING!E8/DATA!D171,0) -> 0 | H33: =IFERROR(PROCESSING!F8/DATA!E171,0) -> 0 | I33: =IFERROR(PROCESSING!G8/DATA!F171,0) -> 0
A34: =SUBTOTAL(3,$C$2:C34) -> 33 | C34: EV/EBITDA | E34: =IFERROR(IF(PROCESSING!C3="","X",PROCESSING!C9/PROCESSING!C3),0) -> X | F34: =IFERROR(IF(PROCESSING!D3="","X",PROCESSING!D9/PROCESSING!D3),0) -> X | G34: =IFERROR(IF(PROCESSING!E3="","X",PROCESSING!E9/PROCESSING!E3),0) -> X | H34: =IFERROR(IF(PROCESSING!F3="","X",PROCESSING!F9/PROCESSING!F3),0) -> X | I34: =IFERROR(IF(PROCESSING!G3="","X",PROCESSING!G9/PROCESSING!G3),0) -> X | K34: ko có chỉ số này trong BCLCTT trực tiếp
A35: =SUBTOTAL(3,$C$2:C35) -> 34 | C35: EV/EBIT | E35: =IFERROR(PROCESSING!C9/PROCESSING!C2,0) -> 0 | F35: =IFERROR(PROCESSING!D9/PROCESSING!D2,0) -> 0 | G35: =IFERROR(PROCESSING!E9/PROCESSING!E2,0) -> 0 | H35: =IFERROR(PROCESSING!F9/PROCESSING!F2,0) -> 0 | I35: =IFERROR(PROCESSING!G9/PROCESSING!G2,0) -> 0
A36: =SUBTOTAL(3,$C$2:C36) -> 35 | C36: EV/Sales | E36: =IFERROR(PROCESSING!C10/DATA!B144,0) -> 0 | F36: =IFERROR(PROCESSING!D10/DATA!C144,0) -> 0 | G36: =IFERROR(PROCESSING!E10/DATA!D144,0) -> 0 | H36: =IFERROR(PROCESSING!F10/DATA!E144,0) -> 0 | I36: =IFERROR(PROCESSING!G10/DATA!F144,0) -> 0
A37: =SUBTOTAL(3,$C$2:C37) -> 36 | C37: Free Cash Flow Yield | D37: FCF Yield | E37: =IFERROR(PROCESSING!C10/PROCESSING!C8,0) -> 0 | F37: =IFERROR(PROCESSING!D10/PROCESSING!D8,0) -> 0 | G37: =IFERROR(PROCESSING!E10/PROCESSING!E8,0) -> 0 | H37: =IFERROR(PROCESSING!F10/PROCESSING!F8,0) -> 0 | I37: =IFERROR(PROCESSING!G10/PROCESSING!G8,0) -> 0
A38: =SUBTOTAL(3,$C$2:C38) -> 37 | C38: Dividend Yield | E38: =IFERROR(IF(DATA!B220="","X",DATA!B220/DATA!$I$3),0) -> X | F38: =IFERROR(IF(DATA!C220="","X",DATA!C220/DATA!$I$3),0) -> X | G38: =IFERROR(IF(DATA!D220="","X",DATA!D220/DATA!$I$3),0) -> X | H38: =IFERROR(IF(DATA!E220="","X",DATA!E220/DATA!$I$3),0) -> X | I38: =IFERROR(IF(DATA!F220="","X",DATA!F220/DATA!$I$3),0) -> X
A39: =SUBTOTAL(3,$C$2:C39) -> 38 | C39: Owner Earnings | E39: =IFERROR(IF(DATA!B182="","X",DATA!B158+DATA!B176-DATA!B195-PROCESSING!C11),0) -> X | F39: =IFERROR(IF(DATA!C182="","X",DATA!C158+DATA!C176-DATA!C195-PROCESSING!D11),0) -> X | G39: =IFERROR(IF(DATA!D182="","X",DATA!D158+DATA!D176-DATA!D195-PROCESSING!E11),0) -> X | H39: =IFERROR(IF(DATA!E182="","X",DATA!E158+DATA!E176-DATA!E195-PROCESSING!F11),0) -> X | I39: =IFERROR(IF(DATA!F182="","X",DATA!F158+DATA!F176-DATA!F195-PROCESSING!G11),0) -> X | K39: ko có chỉ số này trong BCLCTT trực tiếp, maintenance capex tạm thời lấy capex luôn
A40: =SUBTOTAL(3,$C$2:C40) -> 39 | C40: Owner Earnings Yield | E40: =IFERROR(IF(DATA!B182="","X",E39/PROCESSING!C8),0) -> X | F40: =IFERROR(IF(DATA!C182="","X",F39/PROCESSING!D8),0) -> X | G40: =IFERROR(IF(DATA!D182="","X",G39/PROCESSING!E8),0) -> X | H40: =IFERROR(IF(DATA!E182="","X",H39/PROCESSING!F8),0) -> X | I40: =IFERROR(IF(DATA!F182="","X",I39/PROCESSING!G8),0) -> X | K40: ko có chỉ số này trong BCLCTT trực tiếp

Sheet DASHBOARD
